
<mujoco model="iiwa7">
    <compiler angle="radian" meshdir="" />
<!--    <size njmax="500" nconmax="100" />-->

    <option>
        <flag gravity="enable"/>
    </option>

  <include file="allegro_all/allegro_preloads.xml"/>
  <include file="YCB_objects/ycb_preloads.xml"/>

    <visual>
        <map force="10" />
        <scale forcewidth = "0.1"  contactwidth = "0.1" contactheight = "0.1" />
    </visual>

  <default>
    <joint damping="0.01" frictionloss="0"/>
<!--    <default class="visual">-->
<!--      <geom contype="0" conaffinity="0"/>-->
<!--    </default>-->
    <default class="collision0">
      <geom contype="1" conaffinity="1" friction="0.1 0 0.001" solref="-100000 -200" />
    </default>
      <default class="obj">
      <geom condim="6" friction="1 0.5 0.01" solimp="1.1 1.2 0.001 0.5 2" solref="0.02 2"/>
    </default>
     <default class="hand_joint">
      <joint solimplimit="0.9 0.95 0.001 0.5 2"/>
    </default>
      <default class="fingers">
      <geom friction="1 0.5 0.2"  solref="0.02 2"/>
    </default>
      <default class="visual1">
      <geom contype="1" conaffinity="1"/>
    </default>
        <default class="visual2">
     <geom contype="1" conaffinity="1"/>
    </default>
        <default class="visual3">
     <geom contype="1" conaffinity="1"/>
    </default>
        <default class="visual4">
     <geom contype="1" conaffinity="1"/>
    </default>
        <default class="visual5">
      <geom contype="1" conaffinity="1" friction="1 0.8 0.8" solimp="0.8 0.95 0.002 0.5 2" solref="0.02 2"/>
    </default>
      <default class="thumb_test">
      <geom condim="3" contype="1" conaffinity="1" friction="1 0.8 0.8" solimp="0.8 0.95 0.002 0.5 2" solref="0.02 2"/>
    </default>

    <site rgba="1 0 0 .5"/>

        <default class="visual">
          <geom  type="mesh" contype="0" conaffinity="0" />
        </default>
        <default class="collision">
          <geom group="3" type="mesh"  contype="1" conaffinity="1" />
        </default>
  </default>

    <asset>
        <mesh name="link_0" file="iiwa7/link_0.stl" />
        <mesh name="c_link_0" file="iiwa7/c_link_0.stl" />
        <mesh name="link_1" file="iiwa7/link_1.stl" />
        <mesh name="c_link_1" file="iiwa7/c_link_1.stl" />
        <mesh name="link_2" file="iiwa7/link_2.stl" />
        <mesh name="c_link_2" file="iiwa7/c_link_2.stl" />
        <mesh name="link_3" file="iiwa7/link_3.stl" />
        <mesh name="c_link_3" file="iiwa7/c_link_3.stl" />
        <mesh name="link_4" file="iiwa7/link_4.stl" />
        <mesh name="c_link_4" file="iiwa7/c_link_4.stl" />
        <mesh name="link_5" file="iiwa7/link_5.stl" />
        <mesh name="c_link_5" file="iiwa7/c_link_5.stl" />
        <mesh name="link_6" file="iiwa7/link_6.stl" />
        <mesh name="c_link_6" file="iiwa7/c_link_6.stl" />
        <mesh name="link_7" file="iiwa7/link_7.stl" />
        <mesh name="c_link_7" file="iiwa7/c_link_7.stl" />
    </asset>
    <worldbody>
        <light pos="0 0 1000" castshadow="false"/>
        <geom name="floor" class="collision0" type="plane" size="0 0 1" rgba=".8 .8 .8 1"/>
<!--        <geom pos="0 0 0" quat="0 0 1 -1" name="background" class="collision0" type="plane" size="10 10 0.1" rgba="1 1 1 1"/>-->
        <body name="kuka_table" pos="0 0 0.25">
          <geom name="kuka_table" class="collision0" type="box" size=".2 .2 .25" pos="0 0 0"/>
          <body name="kuka_base" pos="0 0 0.25">
            <geom type="mesh" contype="0" conaffinity="0" group="1" rgba="0.4 0.4 0.4 1" mesh="link_0" />
            <geom name="kuka_base" type="mesh" rgba="0.4 0.4 0.4 1" mesh="c_link_0" />
            <body name="iiwa_link_1" pos="0 0 0.15">
                <inertial pos="0 -0.03 0.12" quat="0.428904 0.562175 -0.562175 0.428904" mass="3.4525" diaginertia="0.0218946 0.02183 0.00663837" />
                <joint name="iiwa_joint_1" pos="0 0 0" axis="0 0 1" limited="true" range="-2.96706 2.96706" damping="0.5" />
                <geom pos="0 0 0.0075" type="mesh" contype="0" conaffinity="0" group="1" rgba="1 0.423529 0.0392157 1" mesh="link_1" />
                <geom name="iiwa_link_1" pos="0 0 0.0075" type="mesh" rgba="1 0.423529 0.0392157 1" mesh="c_link_1" />
                <body name="iiwa_link_2" pos="0 0 0.19" quat="0 0 0.707107 0.707107">
                    <inertial pos="0.0003 0.059 0.042" quat="0.701371 0.0898824 0.0898824 0.701371" mass="3.4821" diaginertia="0.02179 0.0217049 0.00684512" />
                    <joint name="iiwa_joint_2" pos="0 0 0" axis="0 0 1" limited="true" range="-2.0944 2.0944" damping="0.5" />
                    <geom type="mesh" contype="0" conaffinity="0" group="1" rgba="1 0.423529 0.0392157 1" mesh="link_2" />
                    <geom name="iiwa_link_2" type="mesh" rgba="1 0.423529 0.0392157 1" mesh="c_link_2" />
                    <body name="iiwa_link_3" pos="0 0.21 0" quat="0 0 0.707107 0.707107">
                        <inertial pos="0 0.03 0.13" quat="0.56292 0.427927 -0.427927 0.56292" mass="4.05623" diaginertia="0.0321488 0.03204 0.00799117" />
                        <joint name="iiwa_joint_3" pos="0 0 0" axis="0 0 1" limited="true" range="-2.96706 2.96706" damping="0.5" />
                        <geom pos="0 0 -0.026" type="mesh" contype="0" conaffinity="0" group="1" rgba="1 0.423529 0.0392157 1" mesh="link_3" />
                        <geom name="iiwa_link_3" pos="0 0 -0.026" type="mesh" rgba="1 0.423529 0.0392157 1" mesh="c_link_3" />
                        <body name="iiwa_link_4" pos="0 0 0.19" quat="0.707107 0.707107 0 0">
                            <inertial pos="0 0.067 0.034" quat="0.991887 -0.127124 0 0" mass="3.4822" diaginertia="0.02178 0.0216947 0.00684029" />
                            <joint name="iiwa_joint_4" pos="0 0 0" axis="0 0 1" limited="true" range="-2.0944 2.0944" damping="0.5" />
                            <geom type="mesh" contype="0" conaffinity="0" group="1" rgba="1 0.423529 0.0392157 1" mesh="link_4" />
                            <geom name="iiwa_link_4" type="mesh" rgba="1 0.423529 0.0392157 1" mesh="c_link_4" />
                            <body name="iiwa_link_5" pos="0 0.21 0" quat="0 0 0.707107 0.707107">
                                <inertial pos="0.0001 0.021 0.076" quat="0.365352 0.605407 -0.605407 0.365352" mass="2.1633" diaginertia="0.0131987 0.01287 0.0036293" />
                                <joint name="iiwa_joint_5" pos="0 0 0" axis="0 0 1" limited="true" range="-2.96706 2.96706" damping="0.5" />
                                <geom pos="0 0 -0.026" type="mesh" contype="0" conaffinity="0" group="1" rgba="1 0.423529 0.0392157 1" mesh="link_5" />
                                <geom name="iiwa_link_5" pos="0 0 -0.026" type="mesh" rgba="1 0.423529 0.0392157 1" mesh="c_link_5" />
                                <body name="iiwa_link_6" pos="0 0.0607 0.19" quat="0.707107 0.707107 0 0">
                                    <inertial pos="0 0.0006 0.0004" quat="0.996112 0.088097 0 0" mass="2.3466" diaginertia="0.006509 0.00631585 0.00447015" />
                                    <joint name="iiwa_joint_6" pos="0 0 0" axis="0 0 1" limited="true" range="-2.0944 2.0944" damping="0.5" />
                                    <geom type="mesh" contype="0" conaffinity="0" group="1" rgba="1 0.423529 0.0392157 1" mesh="link_6" />
                                    <geom name="iiwa_link_6" type="mesh" rgba="1 0.423529 0.0392157 1" mesh="c_link_6" />
                                    <body name="iiwa_link_7" pos="0 0.081 0.0607" quat="0 0 0.707107 0.707107">
                                        <inertial pos="0 0 0.02" quat="0.923068 0 0 0.384636" mass="3.129" diaginertia="1.01524 1.01405 1.00287" />
                                        <joint name="iiwa_joint_7" pos="0 0 0" axis="0 0 1" limited="true" range="-3.05433 3.05433" damping="0.5" />
                                        <geom pos="0 0 -0.0005" type="mesh" contype="0" conaffinity="0" group="1" rgba="0.4 0.4 0.4 1" mesh="link_7" />
                                        <geom name="iiwa_link_7" pos="0 0 -0.0005" type="mesh" rgba="0.4 0.4 0.4 1" mesh="c_link_7" />
                                        <site name="ee_site" pos="0 0 0.0445" euler="0 0 0" size="0.001 0.001 0.001"/>
                                            <body name="allegro_base" euler="0 0 0" pos="0 0 0.0445">
                                                <include file="allegro_all/allegro_left_bodies.xml"/>
                                            </body>
                                        <camera pos="0.1 0 0" euler="3.14159265359 0 -1.57079632679"/>
                                    </body>
                                </body>
                            </body>
                        </body>
                    </body>
                </body>
            </body>
         </body>
         </body>

<!--      <include file="YCB_objects/ycb_bodies.xml"/>-->
        <body name="box1" pos="0.0 0 0.0" gravcomp="1">
          <joint name="box1_joint_x" type="slide" axis="1 0 0"/>
          <joint name="box1_joint_y" type="slide" axis="0 1 0"/>
          <joint name="box1_joint_z" type="slide" axis="0 0 1"/>
          <inertial pos="0 0 0" mass="5.0" diaginertia="0.01 0.01 0.01"/>

          <!-- <geom name="box1_bottom" type="box" size="0.1 0.1 0.005" pos="0 0 -0.02" rgba="0 0 1 1" class="collision0" contype="0" conaffinity="0"/> -->
          <geom name="box1_front" type="box" size="0.1 0.005 0.01" pos="0 0.1 0" rgba="0 0 1 1" class="collision0" contype="0" conaffinity="0"/>
          <geom name="box1_back" type="box" size="0.1 0.005 0.01" pos="0 -0.1 0" rgba="0 0 1 1" class="collision0" contype="0" conaffinity="0"/>
          <geom name="box1_left" type="box" size="0.005 0.1 0.01" pos="-0.1 0 0" rgba="0 0 1 1" class="collision0" contype="0" conaffinity="0"/>
          <geom name="box1_right" type="box" size="0.005 0.1 0.01" pos="0.1 0 0" rgba="0 0 1 1" class="collision0" contype="0" conaffinity="0"/>
        </body>

        <body name="box2" pos="0.0 0 0.0" gravcomp="1">
          <joint name="box2_joint_x" type="slide" axis="1 0 0"/>
          <joint name="box2_joint_y" type="slide" axis="0 1 0"/>
          <joint name="box2_joint_z" type="slide" axis="0 0 1"/>
          <inertial pos="0 0 0" mass="5.0" diaginertia="0.01 0.01 0.01"/>

          <!-- <geom name="box2_bottom" type="box" size="0.1 0.1 0.005" pos="0 0 -0.02" rgba="1 0 0 1" class="collision0" contype="0" conaffinity="0"/> -->
          <geom name="box2_front" type="box" size="0.1 0.005 0.01" pos="0 0.1 0" rgba="1 0 0 1" class="collision0" contype="0" conaffinity="0"/>
          <geom name="box2_back" type="box" size="0.1 0.005 0.01" pos="0 -0.1 0" rgba="1 0 0 1" class="collision0" contype="0" conaffinity="0"/>
          <geom name="box2_left" type="box" size="0.005 0.1 0.01" pos="-0.1 0 0" rgba="1 0 0 1" class="collision0" contype="0" conaffinity="0"/>
          <geom name="box2_right" type="box" size="0.005 0.1 0.01" pos="0.1 0 0" rgba="1 0 0 1" class="collision0" contype="0" conaffinity="0"/>
        </body>

        <body name="box3" pos="0.0 0 0.0" gravcomp="1">
          <joint name="box3_joint_x" type="slide" axis="1 0 0"/>
          <joint name="box3_joint_y" type="slide" axis="0 1 0"/>
          <joint name="box3_joint_z" type="slide" axis="0 0 1"/>
          <inertial pos="0 0 0" mass="5.0" diaginertia="0.01 0.01 0.01"/>

          <!-- <geom name="box3_bottom" type="box" size="0.1 0.1 0.005" pos="0 0 -0.02" rgba="1 1 0 1" class="collision0" contype="0" conaffinity="0"/> -->
          <geom name="box3_front" type="box" size="0.1 0.005 0.01" pos="0 0.1 0" rgba="1 1 0 1" class="collision0" contype="0" conaffinity="0"/>
          <geom name="box3_back" type="box" size="0.1 0.005 0.01" pos="0 -0.1 0" rgba="1 1 0 1" class="collision0" contype="0" conaffinity="0"/>
          <geom name="box3_left" type="box" size="0.005 0.1 0.01" pos="-0.1 0 0" rgba="1 1 0 1" class="collision0" contype="0" conaffinity="0"/>
          <geom name="box3_right" type="box" size="0.005 0.1 0.01" pos="0.1 0 0" rgba="1 1 0 1" class="collision0" contype="0" conaffinity="0"/>
        </body>

        <body name="sphere1" pos="0 0.0 0.0">
            <joint name="sphere1_joint_x" type="slide" axis="1 0 0"/>
            <joint name="sphere1_joint_y" type="slide" axis="0 1 0"/>
            <joint name="sphere1_joint_z" type="slide" axis="0 0 1"/>
            <inertial pos="0 0 0" mass="1.0" diaginertia="0.01 0.01 0.01"/>
            <geom name="sphere1_geom"
              type="sphere"
              size="0.02"
              rgba="0 0 1 1"
              class="collision0"
              contype="0" conaffinity="0"/>
        </body>

        <body name="sphere2" pos="0 0.0 0.0">
            <joint name="sphere2_joint_x" type="slide" axis="1 0 0"/>
            <joint name="sphere2_joint_y" type="slide" axis="0 1 0"/>
            <joint name="sphere2_joint_z" type="slide" axis="0 0 1"/>
            <inertial pos="0 0 0" mass="1.0" diaginertia="0.01 0.01 0.01"/>
            <geom name="sphere2_geom"
              type="sphere"
              size="0.02"
              rgba="1 0 0 1"
              class="collision0"
              contype="0" conaffinity="0"/>
        </body>

        <body name="sphere3" pos="0 0.0 0.0">
            <joint name="sphere3_joint_x" type="slide" axis="1 0 0"/>
            <joint name="sphere3_joint_y" type="slide" axis="0 1 0"/>
            <joint name="sphere3_joint_z" type="slide" axis="0 0 1"/>
            <inertial pos="0 0 0" mass="1.0" diaginertia="0.01 0.01 0.01"/>
            <geom name="sphere3_geom"
              type="sphere"
              size="0.02"
              rgba="1 1 0 1"
              class="collision0"
              contype="0" conaffinity="0"/>
        </body>

        <body name="axes" pos="0 0 0">
            <geom name="x_axis" type="cylinder" size="0.002 3.0" pos="3.0 0 0" euler="0 1.570796 0" rgba="1 0 0 1" contype="0" conaffinity="0"/>
            <geom name="y_axis" type="cylinder" size="0.002 3.0" pos="0 3.0 0" euler="1.570796 0 0" rgba="0 1 0 1" contype="0" conaffinity="0"/>
            <geom name="z_axis" type="cylinder" size="0.002 3.0" pos="0 0 3.0" rgba="0 0 1 1" contype="0" conaffinity="0"/>
        </body>

        <body name="velocity_arrow" pos="0 0 0">
            <geom name="vel_arrow" type="cylinder" size="0.01 0.05"
                rgba="1 0 0 0.8" euler="90 0 0"/>
            <geom name="vel_arrow_head" type="sphere" size="0.02"
                rgba="1 0 0 0.8" pos="0 0 0.07"/>
</body>

    </worldbody>

  <actuator>
      <motor name="iiwa_joint_1" ctrllimited="true" ctrlrange="-300.0 300.0" joint="iiwa_joint_1"/>
      <motor name="iiwa_joint_2" ctrllimited="true" ctrlrange="-300.0 300.0" joint="iiwa_joint_2"/>
      <motor name="iiwa_joint_3" ctrllimited="true" ctrlrange="-300.0 300.0" joint="iiwa_joint_3"/>
      <motor name="iiwa_joint_4" ctrllimited="true" ctrlrange="-300.0 300.0" joint="iiwa_joint_4"/>
      <motor name="iiwa_joint_5" ctrllimited="true" ctrlrange="-300.0 300.0" joint="iiwa_joint_5"/>
      <motor name="iiwa_joint_6" ctrllimited="true" ctrlrange="-300.0 300.0" joint="iiwa_joint_6"/>
      <motor name="iiwa_joint_7" ctrllimited="true" ctrlrange="-300.0 300.0" joint="iiwa_joint_7"/>
      <motor name="index_joint_0" ctrllimited="true" ctrlrange="-15 15" joint="index_joint_0"/>
      <motor name="index_joint_1" ctrllimited="true" ctrlrange="-15 15" joint="index_joint_1"/>
      <motor name="index_joint_2" ctrllimited="true" ctrlrange="-15 15" joint="index_joint_2"/>
      <motor name="index_joint_3" ctrllimited="true" ctrlrange="-15 15" joint="index_joint_3"/>
      <motor name="middle_joint_0" ctrllimited="true" ctrlrange="-15 15" joint="middle_joint_0"/>
      <motor name="middle_joint_1" ctrllimited="true" ctrlrange="-15 15" joint="middle_joint_1"/>
      <motor name="middle_joint_2" ctrllimited="true" ctrlrange="-15 15" joint="middle_joint_2"/>
      <motor name="middle_joint_3" ctrllimited="true" ctrlrange="-15 15" joint="middle_joint_3"/>
      <motor name="ring_joint_0" ctrllimited="true" ctrlrange="-15 15" joint="ring_joint_0"/>
      <motor name="ring_joint_1" ctrllimited="true" ctrlrange="-15 15" joint="ring_joint_1"/>
      <motor name="ring_joint_2" ctrllimited="true" ctrlrange="-15 15" joint="ring_joint_2"/>
      <motor name="ring_joint_3" ctrllimited="true" ctrlrange="-15 15" joint="ring_joint_3"/>
      <motor name="thumb_joint_0" ctrllimited="true" ctrlrange="-15 15" joint="thumb_joint_0"/>
      <motor name="thumb_joint_1" ctrllimited="true" ctrlrange="-15 15" joint="thumb_joint_1"/>
      <motor name="thumb_joint_2" ctrllimited="true" ctrlrange="-15 15" joint="thumb_joint_2"/>
      <motor name="thumb_joint_3" ctrllimited="true" ctrlrange="-15 15" joint="thumb_joint_3"/>
  </actuator>

    <contact>
		<exclude body1="kuka_base" body2="iiwa_link_1"/>
        <exclude body1="iiwa_link_7" body2="sphere1"/>
        <exclude body1="allegro_base" body2="sphere1"/>
        <exclude body1="iiwa_link_7" body2="sphere2"/>
        <exclude body1="allegro_base" body2="sphere2"/>
        <exclude body1="iiwa_link_7" body2="sphere3"/>
        <exclude body1="allegro_base" body2="sphere3"/>

	</contact>



</mujoco>
